[2025-04-04T11:38:24.897+0000] {local_task_job_runner.py:123} INFO - ::group::Pre task execution logs
[2025-04-04T11:38:24.917+0000] {taskinstance.py:2614} INFO - Dependencies all met for dep_context=non-requeueable deps ti=<TaskInstance: weather_data_pipeline.meteo_operations.save_meteo_data scheduled__2025-04-03T00:00:00+00:00 [queued]>
[2025-04-04T11:38:24.924+0000] {taskinstance.py:2614} INFO - Dependencies all met for dep_context=requeueable deps ti=<TaskInstance: weather_data_pipeline.meteo_operations.save_meteo_data scheduled__2025-04-03T00:00:00+00:00 [queued]>
[2025-04-04T11:38:24.925+0000] {taskinstance.py:2867} INFO - Starting attempt 1 of 2
[2025-04-04T11:38:24.936+0000] {taskinstance.py:2890} INFO - Executing <Task(PythonOperator): meteo_operations.save_meteo_data> on 2025-04-03 00:00:00+00:00
[2025-04-04T11:38:24.945+0000] {standard_task_runner.py:104} INFO - Running: ['airflow', 'tasks', 'run', 'weather_data_pipeline', 'meteo_operations.save_meteo_data', 'scheduled__2025-04-03T00:00:00+00:00', '--job-id', '6', '--raw', '--subdir', 'DAGS_FOLDER/operators/testdag.py', '--cfg-path', '/tmp/tmph1jz5mk7']
[2025-04-04T11:38:24.949+0000] {standard_task_runner.py:105} INFO - Job 6: Subtask meteo_operations.save_meteo_data
[2025-04-04T11:38:24.949+0000] {logging_mixin.py:190} WARNING - /home/airflow/.local/lib/python3.12/site-packages/airflow/task/task_runner/standard_task_runner.py:70 DeprecationWarning: This process (pid=122) is multi-threaded, use of fork() may lead to deadlocks in the child.
[2025-04-04T11:38:24.950+0000] {standard_task_runner.py:72} INFO - Started process 140 to run task
[2025-04-04T11:38:25.528+0000] {task_command.py:467} INFO - Running <TaskInstance: weather_data_pipeline.meteo_operations.save_meteo_data scheduled__2025-04-03T00:00:00+00:00 [running]> on host 535fd294ff14
[2025-04-04T11:38:25.620+0000] {taskinstance.py:3134} INFO - Exporting env vars: AIRFLOW_CTX_DAG_OWNER='airflow' AIRFLOW_CTX_DAG_ID='weather_data_pipeline' AIRFLOW_CTX_TASK_ID='meteo_operations.save_meteo_data' AIRFLOW_CTX_EXECUTION_DATE='2025-04-03T00:00:00+00:00' AIRFLOW_CTX_TRY_NUMBER='1' AIRFLOW_CTX_DAG_RUN_ID='scheduled__2025-04-03T00:00:00+00:00'
[2025-04-04T11:38:25.622+0000] {taskinstance.py:732} INFO - ::endgroup::
[2025-04-04T11:38:25.656+0000] {logging_mixin.py:190} INFO - Error saving to database: No location found for coordinates: 21.4901, 39.1862
[2025-04-04T11:38:25.657+0000] {taskinstance.py:3313} ERROR - Task failed with exception
Traceback (most recent call last):
  File "/home/airflow/.local/lib/python3.12/site-packages/airflow/models/taskinstance.py", line 768, in _execute_task
    result = _execute_callable(context=context, **execute_callable_kwargs)
             ^^^^^^^^^^^^^^^^^^^^^^^^^^^^^^^^^^^^^^^^^^^^^^^^^^^^^^^^^^^^^
  File "/home/airflow/.local/lib/python3.12/site-packages/airflow/models/taskinstance.py", line 734, in _execute_callable
    return ExecutionCallableRunner(
           ^^^^^^^^^^^^^^^^^^^^^^^^
  File "/home/airflow/.local/lib/python3.12/site-packages/airflow/utils/operator_helpers.py", line 252, in run
    return self.func(*args, **kwargs)
           ^^^^^^^^^^^^^^^^^^^^^^^^^^
  File "/home/airflow/.local/lib/python3.12/site-packages/airflow/models/baseoperator.py", line 424, in wrapper
    return func(self, *args, **kwargs)
           ^^^^^^^^^^^^^^^^^^^^^^^^^^^
  File "/home/airflow/.local/lib/python3.12/site-packages/airflow/operators/python.py", line 238, in execute
    return_value = self.execute_callable()
                   ^^^^^^^^^^^^^^^^^^^^^^^
  File "/home/airflow/.local/lib/python3.12/site-packages/airflow/operators/python.py", line 256, in execute_callable
    return runner.run(*self.op_args, **self.op_kwargs)
           ^^^^^^^^^^^^^^^^^^^^^^^^^^^^^^^^^^^^^^^^^^^
  File "/home/airflow/.local/lib/python3.12/site-packages/airflow/utils/operator_helpers.py", line 252, in run
    return self.func(*args, **kwargs)
           ^^^^^^^^^^^^^^^^^^^^^^^^^^
  File "/opt/airflow/src/api_client/openmeteo.py", line 89, in insert_measurements_meto
    location_id = get_location_id(conn, location_id, latitude, longitude, "locations")
                  ^^^^^^^^^^^^^^^^^^^^^^^^^^^^^^^^^^^^^^^^^^^^^^^^^^^^^^^^^^^^^^^^^^^^
  File "/opt/airflow/src/db/map.py", line 28, in get_location_id
    raise ValueError(f"No location found for coordinates: {latitude}, {longitude}")
ValueError: No location found for coordinates: 21.4901, 39.1862
[2025-04-04T11:38:25.679+0000] {taskinstance.py:1226} INFO - Marking task as UP_FOR_RETRY. dag_id=weather_data_pipeline, task_id=meteo_operations.save_meteo_data, run_id=scheduled__2025-04-03T00:00:00+00:00, execution_date=20250403T000000, start_date=20250404T113824, end_date=20250404T113825
[2025-04-04T11:38:25.709+0000] {taskinstance.py:341} INFO - ::group::Post task execution logs
[2025-04-04T11:38:25.710+0000] {standard_task_runner.py:124} ERROR - Failed to execute job 6 for task meteo_operations.save_meteo_data (No location found for coordinates: 21.4901, 39.1862; 140)
Traceback (most recent call last):
  File "/home/airflow/.local/lib/python3.12/site-packages/airflow/task/task_runner/standard_task_runner.py", line 117, in _start_by_fork
    ret = args.func(args, dag=self.dag)
          ^^^^^^^^^^^^^^^^^^^^^^^^^^^^^
  File "/home/airflow/.local/lib/python3.12/site-packages/airflow/cli/cli_config.py", line 49, in command
    return func(*args, **kwargs)
           ^^^^^^^^^^^^^^^^^^^^^
  File "/home/airflow/.local/lib/python3.12/site-packages/airflow/utils/cli.py", line 116, in wrapper
    return f(*args, **kwargs)
           ^^^^^^^^^^^^^^^^^^
  File "/home/airflow/.local/lib/python3.12/site-packages/airflow/cli/commands/task_command.py", line 483, in task_run
    task_return_code = _run_task_by_selected_method(args, _dag, ti)
                       ^^^^^^^^^^^^^^^^^^^^^^^^^^^^^^^^^^^^^^^^^^^^
  File "/home/airflow/.local/lib/python3.12/site-packages/airflow/cli/commands/task_command.py", line 256, in _run_task_by_selected_method
    return _run_raw_task(args, ti)
           ^^^^^^^^^^^^^^^^^^^^^^^
  File "/home/airflow/.local/lib/python3.12/site-packages/airflow/cli/commands/task_command.py", line 341, in _run_raw_task
    return ti._run_raw_task(
           ^^^^^^^^^^^^^^^^^
  File "/home/airflow/.local/lib/python3.12/site-packages/airflow/utils/session.py", line 97, in wrapper
    return func(*args, session=session, **kwargs)
           ^^^^^^^^^^^^^^^^^^^^^^^^^^^^^^^^^^^^^^
  File "/home/airflow/.local/lib/python3.12/site-packages/airflow/models/taskinstance.py", line 3006, in _run_raw_task
    return _run_raw_task(
           ^^^^^^^^^^^^^^
  File "/home/airflow/.local/lib/python3.12/site-packages/airflow/models/taskinstance.py", line 274, in _run_raw_task
    TaskInstance._execute_task_with_callbacks(
  File "/home/airflow/.local/lib/python3.12/site-packages/airflow/models/taskinstance.py", line 3161, in _execute_task_with_callbacks
    result = self._execute_task(context, task_orig)
             ^^^^^^^^^^^^^^^^^^^^^^^^^^^^^^^^^^^^^^
  File "/home/airflow/.local/lib/python3.12/site-packages/airflow/models/taskinstance.py", line 3185, in _execute_task
    return _execute_task(self, context, task_orig)
           ^^^^^^^^^^^^^^^^^^^^^^^^^^^^^^^^^^^^^^^
  File "/home/airflow/.local/lib/python3.12/site-packages/airflow/models/taskinstance.py", line 768, in _execute_task
    result = _execute_callable(context=context, **execute_callable_kwargs)
             ^^^^^^^^^^^^^^^^^^^^^^^^^^^^^^^^^^^^^^^^^^^^^^^^^^^^^^^^^^^^^
  File "/home/airflow/.local/lib/python3.12/site-packages/airflow/models/taskinstance.py", line 734, in _execute_callable
    return ExecutionCallableRunner(
           ^^^^^^^^^^^^^^^^^^^^^^^^
  File "/home/airflow/.local/lib/python3.12/site-packages/airflow/utils/operator_helpers.py", line 252, in run
    return self.func(*args, **kwargs)
           ^^^^^^^^^^^^^^^^^^^^^^^^^^
  File "/home/airflow/.local/lib/python3.12/site-packages/airflow/models/baseoperator.py", line 424, in wrapper
    return func(self, *args, **kwargs)
           ^^^^^^^^^^^^^^^^^^^^^^^^^^^
  File "/home/airflow/.local/lib/python3.12/site-packages/airflow/operators/python.py", line 238, in execute
    return_value = self.execute_callable()
                   ^^^^^^^^^^^^^^^^^^^^^^^
  File "/home/airflow/.local/lib/python3.12/site-packages/airflow/operators/python.py", line 256, in execute_callable
    return runner.run(*self.op_args, **self.op_kwargs)
           ^^^^^^^^^^^^^^^^^^^^^^^^^^^^^^^^^^^^^^^^^^^
  File "/home/airflow/.local/lib/python3.12/site-packages/airflow/utils/operator_helpers.py", line 252, in run
    return self.func(*args, **kwargs)
           ^^^^^^^^^^^^^^^^^^^^^^^^^^
  File "/opt/airflow/src/api_client/openmeteo.py", line 89, in insert_measurements_meto
    location_id = get_location_id(conn, location_id, latitude, longitude, "locations")
                  ^^^^^^^^^^^^^^^^^^^^^^^^^^^^^^^^^^^^^^^^^^^^^^^^^^^^^^^^^^^^^^^^^^^^
  File "/opt/airflow/src/db/map.py", line 28, in get_location_id
    raise ValueError(f"No location found for coordinates: {latitude}, {longitude}")
ValueError: No location found for coordinates: 21.4901, 39.1862
[2025-04-04T11:38:25.729+0000] {local_task_job_runner.py:266} INFO - Task exited with return code 1
[2025-04-04T11:38:25.751+0000] {taskinstance.py:3901} INFO - 0 downstream tasks scheduled from follow-on schedule check
[2025-04-04T11:38:25.753+0000] {local_task_job_runner.py:245} INFO - ::endgroup::
[2025-04-04T11:40:53.897+0000] {local_task_job_runner.py:123} INFO - ::group::Pre task execution logs
[2025-04-04T11:40:53.921+0000] {taskinstance.py:2614} INFO - Dependencies all met for dep_context=non-requeueable deps ti=<TaskInstance: weather_data_pipeline.meteo_operations.save_meteo_data scheduled__2025-04-03T00:00:00+00:00 [queued]>
[2025-04-04T11:40:53.931+0000] {taskinstance.py:2614} INFO - Dependencies all met for dep_context=requeueable deps ti=<TaskInstance: weather_data_pipeline.meteo_operations.save_meteo_data scheduled__2025-04-03T00:00:00+00:00 [queued]>
[2025-04-04T11:40:53.931+0000] {taskinstance.py:2867} INFO - Starting attempt 1 of 2
[2025-04-04T11:40:53.943+0000] {taskinstance.py:2890} INFO - Executing <Task(PythonOperator): meteo_operations.save_meteo_data> on 2025-04-03 00:00:00+00:00
[2025-04-04T11:40:53.951+0000] {standard_task_runner.py:104} INFO - Running: ['airflow', 'tasks', 'run', 'weather_data_pipeline', 'meteo_operations.save_meteo_data', 'scheduled__2025-04-03T00:00:00+00:00', '--job-id', '6', '--raw', '--subdir', 'DAGS_FOLDER/operators/testdag.py', '--cfg-path', '/tmp/tmpi94442yb']
[2025-04-04T11:40:53.954+0000] {standard_task_runner.py:105} INFO - Job 6: Subtask meteo_operations.save_meteo_data
[2025-04-04T11:40:53.956+0000] {logging_mixin.py:190} WARNING - /home/airflow/.local/lib/python3.12/site-packages/airflow/task/task_runner/standard_task_runner.py:70 DeprecationWarning: This process (pid=121) is multi-threaded, use of fork() may lead to deadlocks in the child.
[2025-04-04T11:40:53.957+0000] {standard_task_runner.py:72} INFO - Started process 140 to run task
[2025-04-04T11:40:54.013+0000] {task_command.py:467} INFO - Running <TaskInstance: weather_data_pipeline.meteo_operations.save_meteo_data scheduled__2025-04-03T00:00:00+00:00 [running]> on host d670f735fdc0
[2025-04-04T11:40:54.096+0000] {taskinstance.py:3134} INFO - Exporting env vars: AIRFLOW_CTX_DAG_OWNER='airflow' AIRFLOW_CTX_DAG_ID='weather_data_pipeline' AIRFLOW_CTX_TASK_ID='meteo_operations.save_meteo_data' AIRFLOW_CTX_EXECUTION_DATE='2025-04-03T00:00:00+00:00' AIRFLOW_CTX_TRY_NUMBER='1' AIRFLOW_CTX_DAG_RUN_ID='scheduled__2025-04-03T00:00:00+00:00'
[2025-04-04T11:40:54.097+0000] {taskinstance.py:732} INFO - ::endgroup::
[2025-04-04T11:40:54.133+0000] {python.py:240} INFO - Done. Returned value was: Successfully inserted measurement into database
[2025-04-04T11:40:54.161+0000] {taskinstance.py:341} INFO - ::group::Post task execution logs
[2025-04-04T11:40:54.162+0000] {taskinstance.py:353} INFO - Marking task as SUCCESS. dag_id=weather_data_pipeline, task_id=meteo_operations.save_meteo_data, run_id=scheduled__2025-04-03T00:00:00+00:00, execution_date=20250403T000000, start_date=20250404T114053, end_date=20250404T114054
[2025-04-04T11:40:54.213+0000] {local_task_job_runner.py:266} INFO - Task exited with return code 0
[2025-04-04T11:40:54.235+0000] {taskinstance.py:3901} INFO - 0 downstream tasks scheduled from follow-on schedule check
[2025-04-04T11:40:54.237+0000] {local_task_job_runner.py:245} INFO - ::endgroup::
