[2025-04-04T11:27:13.936+0000] {local_task_job_runner.py:123} INFO - ::group::Pre task execution logs
[2025-04-04T11:27:13.957+0000] {taskinstance.py:2614} INFO - Dependencies all met for dep_context=non-requeueable deps ti=<TaskInstance: weather_data_pipeline.meteo_operations.save_meteo_data scheduled__2025-04-03T00:00:00+00:00 [queued]>
[2025-04-04T11:27:13.967+0000] {taskinstance.py:2614} INFO - Dependencies all met for dep_context=requeueable deps ti=<TaskInstance: weather_data_pipeline.meteo_operations.save_meteo_data scheduled__2025-04-03T00:00:00+00:00 [queued]>
[2025-04-04T11:27:13.968+0000] {taskinstance.py:2867} INFO - Starting attempt 2 of 2
[2025-04-04T11:27:13.979+0000] {taskinstance.py:2890} INFO - Executing <Task(PythonOperator): meteo_operations.save_meteo_data> on 2025-04-03 00:00:00+00:00
[2025-04-04T11:27:13.987+0000] {standard_task_runner.py:104} INFO - Running: ['airflow', 'tasks', 'run', 'weather_data_pipeline', 'meteo_operations.save_meteo_data', 'scheduled__2025-04-03T00:00:00+00:00', '--job-id', '16', '--raw', '--subdir', 'DAGS_FOLDER/operators/testdag.py', '--cfg-path', '/tmp/tmp1s_ryat0']
[2025-04-04T11:27:13.990+0000] {standard_task_runner.py:105} INFO - Job 16: Subtask meteo_operations.save_meteo_data
[2025-04-04T11:27:13.992+0000] {logging_mixin.py:190} WARNING - /home/airflow/.local/lib/python3.12/site-packages/airflow/task/task_runner/standard_task_runner.py:70 DeprecationWarning: This process (pid=38) is multi-threaded, use of fork() may lead to deadlocks in the child.
[2025-04-04T11:27:13.993+0000] {standard_task_runner.py:72} INFO - Started process 56 to run task
[2025-04-04T11:27:14.042+0000] {task_command.py:467} INFO - Running <TaskInstance: weather_data_pipeline.meteo_operations.save_meteo_data scheduled__2025-04-03T00:00:00+00:00 [running]> on host ff257e555ae6
[2025-04-04T11:27:14.127+0000] {taskinstance.py:3134} INFO - Exporting env vars: AIRFLOW_CTX_DAG_OWNER='airflow' AIRFLOW_CTX_DAG_ID='weather_data_pipeline' AIRFLOW_CTX_TASK_ID='meteo_operations.save_meteo_data' AIRFLOW_CTX_EXECUTION_DATE='2025-04-03T00:00:00+00:00' AIRFLOW_CTX_TRY_NUMBER='2' AIRFLOW_CTX_DAG_RUN_ID='scheduled__2025-04-03T00:00:00+00:00'
[2025-04-04T11:27:14.128+0000] {taskinstance.py:732} INFO - ::endgroup::
[2025-04-04T11:27:14.171+0000] {logging_mixin.py:190} INFO - Error saving to database: No location found for coordinates: 21.4901, 39.1862
[2025-04-04T11:27:14.172+0000] {taskinstance.py:3313} ERROR - Task failed with exception
Traceback (most recent call last):
  File "/home/airflow/.local/lib/python3.12/site-packages/airflow/models/taskinstance.py", line 768, in _execute_task
    result = _execute_callable(context=context, **execute_callable_kwargs)
             ^^^^^^^^^^^^^^^^^^^^^^^^^^^^^^^^^^^^^^^^^^^^^^^^^^^^^^^^^^^^^
  File "/home/airflow/.local/lib/python3.12/site-packages/airflow/models/taskinstance.py", line 734, in _execute_callable
    return ExecutionCallableRunner(
           ^^^^^^^^^^^^^^^^^^^^^^^^
  File "/home/airflow/.local/lib/python3.12/site-packages/airflow/utils/operator_helpers.py", line 252, in run
    return self.func(*args, **kwargs)
           ^^^^^^^^^^^^^^^^^^^^^^^^^^
  File "/home/airflow/.local/lib/python3.12/site-packages/airflow/models/baseoperator.py", line 424, in wrapper
    return func(self, *args, **kwargs)
           ^^^^^^^^^^^^^^^^^^^^^^^^^^^
  File "/home/airflow/.local/lib/python3.12/site-packages/airflow/operators/python.py", line 238, in execute
    return_value = self.execute_callable()
                   ^^^^^^^^^^^^^^^^^^^^^^^
  File "/home/airflow/.local/lib/python3.12/site-packages/airflow/operators/python.py", line 256, in execute_callable
    return runner.run(*self.op_args, **self.op_kwargs)
           ^^^^^^^^^^^^^^^^^^^^^^^^^^^^^^^^^^^^^^^^^^^
  File "/home/airflow/.local/lib/python3.12/site-packages/airflow/utils/operator_helpers.py", line 252, in run
    return self.func(*args, **kwargs)
           ^^^^^^^^^^^^^^^^^^^^^^^^^^
  File "/opt/airflow/src/api_client/openmeteo.py", line 89, in insert_measurements_meto
    location_id = get_location_id(conn, location_id, latitude, longitude, "locations")
                  ^^^^^^^^^^^^^^^^^^^^^^^^^^^^^^^^^^^^^^^^^^^^^^^^^^^^^^^^^^^^^^^^^^^^
  File "/opt/airflow/src/db/map.py", line 28, in get_location_id
    raise ValueError(f"No location found for coordinates: {latitude}, {longitude}")
ValueError: No location found for coordinates: 21.4901, 39.1862
[2025-04-04T11:27:14.191+0000] {taskinstance.py:1226} INFO - Marking task as FAILED. dag_id=weather_data_pipeline, task_id=meteo_operations.save_meteo_data, run_id=scheduled__2025-04-03T00:00:00+00:00, execution_date=20250403T000000, start_date=20250404T112713, end_date=20250404T112714
[2025-04-04T11:27:14.222+0000] {taskinstance.py:341} INFO - ::group::Post task execution logs
[2025-04-04T11:27:14.222+0000] {standard_task_runner.py:124} ERROR - Failed to execute job 16 for task meteo_operations.save_meteo_data (No location found for coordinates: 21.4901, 39.1862; 56)
Traceback (most recent call last):
  File "/home/airflow/.local/lib/python3.12/site-packages/airflow/task/task_runner/standard_task_runner.py", line 117, in _start_by_fork
    ret = args.func(args, dag=self.dag)
          ^^^^^^^^^^^^^^^^^^^^^^^^^^^^^
  File "/home/airflow/.local/lib/python3.12/site-packages/airflow/cli/cli_config.py", line 49, in command
    return func(*args, **kwargs)
           ^^^^^^^^^^^^^^^^^^^^^
  File "/home/airflow/.local/lib/python3.12/site-packages/airflow/utils/cli.py", line 116, in wrapper
    return f(*args, **kwargs)
           ^^^^^^^^^^^^^^^^^^
  File "/home/airflow/.local/lib/python3.12/site-packages/airflow/cli/commands/task_command.py", line 483, in task_run
    task_return_code = _run_task_by_selected_method(args, _dag, ti)
                       ^^^^^^^^^^^^^^^^^^^^^^^^^^^^^^^^^^^^^^^^^^^^
  File "/home/airflow/.local/lib/python3.12/site-packages/airflow/cli/commands/task_command.py", line 256, in _run_task_by_selected_method
    return _run_raw_task(args, ti)
           ^^^^^^^^^^^^^^^^^^^^^^^
  File "/home/airflow/.local/lib/python3.12/site-packages/airflow/cli/commands/task_command.py", line 341, in _run_raw_task
    return ti._run_raw_task(
           ^^^^^^^^^^^^^^^^^
  File "/home/airflow/.local/lib/python3.12/site-packages/airflow/utils/session.py", line 97, in wrapper
    return func(*args, session=session, **kwargs)
           ^^^^^^^^^^^^^^^^^^^^^^^^^^^^^^^^^^^^^^
  File "/home/airflow/.local/lib/python3.12/site-packages/airflow/models/taskinstance.py", line 3006, in _run_raw_task
    return _run_raw_task(
           ^^^^^^^^^^^^^^
  File "/home/airflow/.local/lib/python3.12/site-packages/airflow/models/taskinstance.py", line 274, in _run_raw_task
    TaskInstance._execute_task_with_callbacks(
  File "/home/airflow/.local/lib/python3.12/site-packages/airflow/models/taskinstance.py", line 3161, in _execute_task_with_callbacks
    result = self._execute_task(context, task_orig)
             ^^^^^^^^^^^^^^^^^^^^^^^^^^^^^^^^^^^^^^
  File "/home/airflow/.local/lib/python3.12/site-packages/airflow/models/taskinstance.py", line 3185, in _execute_task
    return _execute_task(self, context, task_orig)
           ^^^^^^^^^^^^^^^^^^^^^^^^^^^^^^^^^^^^^^^
  File "/home/airflow/.local/lib/python3.12/site-packages/airflow/models/taskinstance.py", line 768, in _execute_task
    result = _execute_callable(context=context, **execute_callable_kwargs)
             ^^^^^^^^^^^^^^^^^^^^^^^^^^^^^^^^^^^^^^^^^^^^^^^^^^^^^^^^^^^^^
  File "/home/airflow/.local/lib/python3.12/site-packages/airflow/models/taskinstance.py", line 734, in _execute_callable
    return ExecutionCallableRunner(
           ^^^^^^^^^^^^^^^^^^^^^^^^
  File "/home/airflow/.local/lib/python3.12/site-packages/airflow/utils/operator_helpers.py", line 252, in run
    return self.func(*args, **kwargs)
           ^^^^^^^^^^^^^^^^^^^^^^^^^^
  File "/home/airflow/.local/lib/python3.12/site-packages/airflow/models/baseoperator.py", line 424, in wrapper
    return func(self, *args, **kwargs)
           ^^^^^^^^^^^^^^^^^^^^^^^^^^^
  File "/home/airflow/.local/lib/python3.12/site-packages/airflow/operators/python.py", line 238, in execute
    return_value = self.execute_callable()
                   ^^^^^^^^^^^^^^^^^^^^^^^
  File "/home/airflow/.local/lib/python3.12/site-packages/airflow/operators/python.py", line 256, in execute_callable
    return runner.run(*self.op_args, **self.op_kwargs)
           ^^^^^^^^^^^^^^^^^^^^^^^^^^^^^^^^^^^^^^^^^^^
  File "/home/airflow/.local/lib/python3.12/site-packages/airflow/utils/operator_helpers.py", line 252, in run
    return self.func(*args, **kwargs)
           ^^^^^^^^^^^^^^^^^^^^^^^^^^
  File "/opt/airflow/src/api_client/openmeteo.py", line 89, in insert_measurements_meto
    location_id = get_location_id(conn, location_id, latitude, longitude, "locations")
                  ^^^^^^^^^^^^^^^^^^^^^^^^^^^^^^^^^^^^^^^^^^^^^^^^^^^^^^^^^^^^^^^^^^^^
  File "/opt/airflow/src/db/map.py", line 28, in get_location_id
    raise ValueError(f"No location found for coordinates: {latitude}, {longitude}")
ValueError: No location found for coordinates: 21.4901, 39.1862
[2025-04-04T11:27:14.248+0000] {local_task_job_runner.py:266} INFO - Task exited with return code 1
[2025-04-04T11:27:14.276+0000] {taskinstance.py:3901} INFO - 0 downstream tasks scheduled from follow-on schedule check
[2025-04-04T11:27:14.280+0000] {local_task_job_runner.py:245} INFO - ::endgroup::
