[2025-04-04T11:38:29.532+0000] {local_task_job_runner.py:123} INFO - ::group::Pre task execution logs
[2025-04-04T11:38:29.551+0000] {taskinstance.py:2614} INFO - Dependencies all met for dep_context=non-requeueable deps ti=<TaskInstance: weather_data_pipeline.openweather_operations.save_openweather_data scheduled__2025-04-03T00:00:00+00:00 [queued]>
[2025-04-04T11:38:29.558+0000] {taskinstance.py:2614} INFO - Dependencies all met for dep_context=requeueable deps ti=<TaskInstance: weather_data_pipeline.openweather_operations.save_openweather_data scheduled__2025-04-03T00:00:00+00:00 [queued]>
[2025-04-04T11:38:29.559+0000] {taskinstance.py:2867} INFO - Starting attempt 1 of 2
[2025-04-04T11:38:29.569+0000] {taskinstance.py:2890} INFO - Executing <Task(PythonOperator): openweather_operations.save_openweather_data> on 2025-04-03 00:00:00+00:00
[2025-04-04T11:38:29.576+0000] {standard_task_runner.py:104} INFO - Running: ['airflow', 'tasks', 'run', 'weather_data_pipeline', 'openweather_operations.save_openweather_data', 'scheduled__2025-04-03T00:00:00+00:00', '--job-id', '7', '--raw', '--subdir', 'DAGS_FOLDER/operators/testdag.py', '--cfg-path', '/tmp/tmpt3oibu6n']
[2025-04-04T11:38:29.579+0000] {standard_task_runner.py:105} INFO - Job 7: Subtask openweather_operations.save_openweather_data
[2025-04-04T11:38:29.580+0000] {logging_mixin.py:190} WARNING - /home/airflow/.local/lib/python3.12/site-packages/airflow/task/task_runner/standard_task_runner.py:70 DeprecationWarning: This process (pid=142) is multi-threaded, use of fork() may lead to deadlocks in the child.
[2025-04-04T11:38:29.581+0000] {standard_task_runner.py:72} INFO - Started process 160 to run task
[2025-04-04T11:38:29.630+0000] {task_command.py:467} INFO - Running <TaskInstance: weather_data_pipeline.openweather_operations.save_openweather_data scheduled__2025-04-03T00:00:00+00:00 [running]> on host 535fd294ff14
[2025-04-04T11:38:29.701+0000] {taskinstance.py:3134} INFO - Exporting env vars: AIRFLOW_CTX_DAG_OWNER='airflow' AIRFLOW_CTX_DAG_ID='weather_data_pipeline' AIRFLOW_CTX_TASK_ID='openweather_operations.save_openweather_data' AIRFLOW_CTX_EXECUTION_DATE='2025-04-03T00:00:00+00:00' AIRFLOW_CTX_TRY_NUMBER='1' AIRFLOW_CTX_DAG_RUN_ID='scheduled__2025-04-03T00:00:00+00:00'
[2025-04-04T11:38:29.702+0000] {taskinstance.py:732} INFO - ::endgroup::
[2025-04-04T11:38:29.731+0000] {logging_mixin.py:190} INFO - Creating OpenWeatherMap organization record
[2025-04-04T11:38:29.733+0000] {logging_mixin.py:190} INFO - Error inserting measurements: No location found for coordinates: 24.7136, 46.6753
[2025-04-04T11:38:29.734+0000] {taskinstance.py:3313} ERROR - Task failed with exception
Traceback (most recent call last):
  File "/home/airflow/.local/lib/python3.12/site-packages/airflow/models/taskinstance.py", line 768, in _execute_task
    result = _execute_callable(context=context, **execute_callable_kwargs)
             ^^^^^^^^^^^^^^^^^^^^^^^^^^^^^^^^^^^^^^^^^^^^^^^^^^^^^^^^^^^^^
  File "/home/airflow/.local/lib/python3.12/site-packages/airflow/models/taskinstance.py", line 734, in _execute_callable
    return ExecutionCallableRunner(
           ^^^^^^^^^^^^^^^^^^^^^^^^
  File "/home/airflow/.local/lib/python3.12/site-packages/airflow/utils/operator_helpers.py", line 252, in run
    return self.func(*args, **kwargs)
           ^^^^^^^^^^^^^^^^^^^^^^^^^^
  File "/home/airflow/.local/lib/python3.12/site-packages/airflow/models/baseoperator.py", line 424, in wrapper
    return func(self, *args, **kwargs)
           ^^^^^^^^^^^^^^^^^^^^^^^^^^^
  File "/home/airflow/.local/lib/python3.12/site-packages/airflow/operators/python.py", line 238, in execute
    return_value = self.execute_callable()
                   ^^^^^^^^^^^^^^^^^^^^^^^
  File "/home/airflow/.local/lib/python3.12/site-packages/airflow/operators/python.py", line 256, in execute_callable
    return runner.run(*self.op_args, **self.op_kwargs)
           ^^^^^^^^^^^^^^^^^^^^^^^^^^^^^^^^^^^^^^^^^^^
  File "/home/airflow/.local/lib/python3.12/site-packages/airflow/utils/operator_helpers.py", line 252, in run
    return self.func(*args, **kwargs)
           ^^^^^^^^^^^^^^^^^^^^^^^^^^
  File "/opt/airflow/src/api_client/openweathermap_API.py", line 98, in insert_measurements_openweathermap
    location_id = get_location_id(conn, "location_id", record['lat'], record['lon'], "locations")
                  ^^^^^^^^^^^^^^^^^^^^^^^^^^^^^^^^^^^^^^^^^^^^^^^^^^^^^^^^^^^^^^^^^^^^^^^^^^^^^^^
  File "/opt/airflow/src/db/map.py", line 28, in get_location_id
    raise ValueError(f"No location found for coordinates: {latitude}, {longitude}")
ValueError: No location found for coordinates: 24.7136, 46.6753
[2025-04-04T11:38:29.754+0000] {taskinstance.py:1226} INFO - Marking task as UP_FOR_RETRY. dag_id=weather_data_pipeline, task_id=openweather_operations.save_openweather_data, run_id=scheduled__2025-04-03T00:00:00+00:00, execution_date=20250403T000000, start_date=20250404T113829, end_date=20250404T113829
[2025-04-04T11:38:29.781+0000] {taskinstance.py:341} INFO - ::group::Post task execution logs
[2025-04-04T11:38:29.781+0000] {standard_task_runner.py:124} ERROR - Failed to execute job 7 for task openweather_operations.save_openweather_data (No location found for coordinates: 24.7136, 46.6753; 160)
Traceback (most recent call last):
  File "/home/airflow/.local/lib/python3.12/site-packages/airflow/task/task_runner/standard_task_runner.py", line 117, in _start_by_fork
    ret = args.func(args, dag=self.dag)
          ^^^^^^^^^^^^^^^^^^^^^^^^^^^^^
  File "/home/airflow/.local/lib/python3.12/site-packages/airflow/cli/cli_config.py", line 49, in command
    return func(*args, **kwargs)
           ^^^^^^^^^^^^^^^^^^^^^
  File "/home/airflow/.local/lib/python3.12/site-packages/airflow/utils/cli.py", line 116, in wrapper
    return f(*args, **kwargs)
           ^^^^^^^^^^^^^^^^^^
  File "/home/airflow/.local/lib/python3.12/site-packages/airflow/cli/commands/task_command.py", line 483, in task_run
    task_return_code = _run_task_by_selected_method(args, _dag, ti)
                       ^^^^^^^^^^^^^^^^^^^^^^^^^^^^^^^^^^^^^^^^^^^^
  File "/home/airflow/.local/lib/python3.12/site-packages/airflow/cli/commands/task_command.py", line 256, in _run_task_by_selected_method
    return _run_raw_task(args, ti)
           ^^^^^^^^^^^^^^^^^^^^^^^
  File "/home/airflow/.local/lib/python3.12/site-packages/airflow/cli/commands/task_command.py", line 341, in _run_raw_task
    return ti._run_raw_task(
           ^^^^^^^^^^^^^^^^^
  File "/home/airflow/.local/lib/python3.12/site-packages/airflow/utils/session.py", line 97, in wrapper
    return func(*args, session=session, **kwargs)
           ^^^^^^^^^^^^^^^^^^^^^^^^^^^^^^^^^^^^^^
  File "/home/airflow/.local/lib/python3.12/site-packages/airflow/models/taskinstance.py", line 3006, in _run_raw_task
    return _run_raw_task(
           ^^^^^^^^^^^^^^
  File "/home/airflow/.local/lib/python3.12/site-packages/airflow/models/taskinstance.py", line 274, in _run_raw_task
    TaskInstance._execute_task_with_callbacks(
  File "/home/airflow/.local/lib/python3.12/site-packages/airflow/models/taskinstance.py", line 3161, in _execute_task_with_callbacks
    result = self._execute_task(context, task_orig)
             ^^^^^^^^^^^^^^^^^^^^^^^^^^^^^^^^^^^^^^
  File "/home/airflow/.local/lib/python3.12/site-packages/airflow/models/taskinstance.py", line 3185, in _execute_task
    return _execute_task(self, context, task_orig)
           ^^^^^^^^^^^^^^^^^^^^^^^^^^^^^^^^^^^^^^^
  File "/home/airflow/.local/lib/python3.12/site-packages/airflow/models/taskinstance.py", line 768, in _execute_task
    result = _execute_callable(context=context, **execute_callable_kwargs)
             ^^^^^^^^^^^^^^^^^^^^^^^^^^^^^^^^^^^^^^^^^^^^^^^^^^^^^^^^^^^^^
  File "/home/airflow/.local/lib/python3.12/site-packages/airflow/models/taskinstance.py", line 734, in _execute_callable
    return ExecutionCallableRunner(
           ^^^^^^^^^^^^^^^^^^^^^^^^
  File "/home/airflow/.local/lib/python3.12/site-packages/airflow/utils/operator_helpers.py", line 252, in run
    return self.func(*args, **kwargs)
           ^^^^^^^^^^^^^^^^^^^^^^^^^^
  File "/home/airflow/.local/lib/python3.12/site-packages/airflow/models/baseoperator.py", line 424, in wrapper
    return func(self, *args, **kwargs)
           ^^^^^^^^^^^^^^^^^^^^^^^^^^^
  File "/home/airflow/.local/lib/python3.12/site-packages/airflow/operators/python.py", line 238, in execute
    return_value = self.execute_callable()
                   ^^^^^^^^^^^^^^^^^^^^^^^
  File "/home/airflow/.local/lib/python3.12/site-packages/airflow/operators/python.py", line 256, in execute_callable
    return runner.run(*self.op_args, **self.op_kwargs)
           ^^^^^^^^^^^^^^^^^^^^^^^^^^^^^^^^^^^^^^^^^^^
  File "/home/airflow/.local/lib/python3.12/site-packages/airflow/utils/operator_helpers.py", line 252, in run
    return self.func(*args, **kwargs)
           ^^^^^^^^^^^^^^^^^^^^^^^^^^
  File "/opt/airflow/src/api_client/openweathermap_API.py", line 98, in insert_measurements_openweathermap
    location_id = get_location_id(conn, "location_id", record['lat'], record['lon'], "locations")
                  ^^^^^^^^^^^^^^^^^^^^^^^^^^^^^^^^^^^^^^^^^^^^^^^^^^^^^^^^^^^^^^^^^^^^^^^^^^^^^^^
  File "/opt/airflow/src/db/map.py", line 28, in get_location_id
    raise ValueError(f"No location found for coordinates: {latitude}, {longitude}")
ValueError: No location found for coordinates: 24.7136, 46.6753
[2025-04-04T11:38:29.795+0000] {local_task_job_runner.py:266} INFO - Task exited with return code 1
[2025-04-04T11:38:29.816+0000] {taskinstance.py:3901} INFO - 0 downstream tasks scheduled from follow-on schedule check
[2025-04-04T11:38:29.818+0000] {local_task_job_runner.py:245} INFO - ::endgroup::
[2025-04-04T11:40:58.693+0000] {local_task_job_runner.py:123} INFO - ::group::Pre task execution logs
[2025-04-04T11:40:58.716+0000] {taskinstance.py:2614} INFO - Dependencies all met for dep_context=non-requeueable deps ti=<TaskInstance: weather_data_pipeline.openweather_operations.save_openweather_data scheduled__2025-04-03T00:00:00+00:00 [queued]>
[2025-04-04T11:40:58.726+0000] {taskinstance.py:2614} INFO - Dependencies all met for dep_context=requeueable deps ti=<TaskInstance: weather_data_pipeline.openweather_operations.save_openweather_data scheduled__2025-04-03T00:00:00+00:00 [queued]>
[2025-04-04T11:40:58.727+0000] {taskinstance.py:2867} INFO - Starting attempt 1 of 2
[2025-04-04T11:40:58.740+0000] {taskinstance.py:2890} INFO - Executing <Task(PythonOperator): openweather_operations.save_openweather_data> on 2025-04-03 00:00:00+00:00
[2025-04-04T11:40:58.748+0000] {standard_task_runner.py:104} INFO - Running: ['airflow', 'tasks', 'run', 'weather_data_pipeline', 'openweather_operations.save_openweather_data', 'scheduled__2025-04-03T00:00:00+00:00', '--job-id', '7', '--raw', '--subdir', 'DAGS_FOLDER/operators/testdag.py', '--cfg-path', '/tmp/tmpo4u2mx21']
[2025-04-04T11:40:58.752+0000] {standard_task_runner.py:105} INFO - Job 7: Subtask openweather_operations.save_openweather_data
[2025-04-04T11:40:58.754+0000] {logging_mixin.py:190} WARNING - /home/airflow/.local/lib/python3.12/site-packages/airflow/task/task_runner/standard_task_runner.py:70 DeprecationWarning: This process (pid=142) is multi-threaded, use of fork() may lead to deadlocks in the child.
[2025-04-04T11:40:58.755+0000] {standard_task_runner.py:72} INFO - Started process 160 to run task
[2025-04-04T11:40:58.817+0000] {task_command.py:467} INFO - Running <TaskInstance: weather_data_pipeline.openweather_operations.save_openweather_data scheduled__2025-04-03T00:00:00+00:00 [running]> on host d670f735fdc0
[2025-04-04T11:40:58.902+0000] {taskinstance.py:3134} INFO - Exporting env vars: AIRFLOW_CTX_DAG_OWNER='airflow' AIRFLOW_CTX_DAG_ID='weather_data_pipeline' AIRFLOW_CTX_TASK_ID='openweather_operations.save_openweather_data' AIRFLOW_CTX_EXECUTION_DATE='2025-04-03T00:00:00+00:00' AIRFLOW_CTX_TRY_NUMBER='1' AIRFLOW_CTX_DAG_RUN_ID='scheduled__2025-04-03T00:00:00+00:00'
[2025-04-04T11:40:58.904+0000] {taskinstance.py:732} INFO - ::endgroup::
[2025-04-04T11:40:58.944+0000] {logging_mixin.py:190} INFO - Inserted data for Riyadh
[2025-04-04T11:40:58.949+0000] {logging_mixin.py:190} INFO - Inserted data for Jeddah
[2025-04-04T11:40:58.954+0000] {logging_mixin.py:190} INFO - Inserted data for Mecca
[2025-04-04T11:40:58.959+0000] {logging_mixin.py:190} INFO - Inserted data for Medina
[2025-04-04T11:40:58.965+0000] {logging_mixin.py:190} INFO - Inserted data for Dammam
[2025-04-04T11:40:58.971+0000] {logging_mixin.py:190} INFO - Inserted data for Taif
[2025-04-04T11:40:58.971+0000] {python.py:240} INFO - Done. Returned value was: Successfully inserted measurement into database
[2025-04-04T11:40:59.348+0000] {taskinstance.py:341} INFO - ::group::Post task execution logs
[2025-04-04T11:40:59.349+0000] {taskinstance.py:353} INFO - Marking task as SUCCESS. dag_id=weather_data_pipeline, task_id=openweather_operations.save_openweather_data, run_id=scheduled__2025-04-03T00:00:00+00:00, execution_date=20250403T000000, start_date=20250404T114058, end_date=20250404T114059
[2025-04-04T11:40:59.403+0000] {local_task_job_runner.py:266} INFO - Task exited with return code 0
[2025-04-04T11:40:59.950+0000] {taskinstance.py:3901} INFO - 0 downstream tasks scheduled from follow-on schedule check
[2025-04-04T11:40:59.952+0000] {local_task_job_runner.py:245} INFO - ::endgroup::
