[2025-04-22T22:30:19.793+0000] {taskinstance.py:1159} INFO - Dependencies all met for dep_context=non-requeueable deps ti=<TaskInstance: weather_data_pipeline.ai_forecast_operations.forecast_pm25_org1 manual__2025-04-22T22:29:36.102757+00:00 [queued]>
[2025-04-22T22:30:19.799+0000] {taskinstance.py:1159} INFO - Dependencies all met for dep_context=requeueable deps ti=<TaskInstance: weather_data_pipeline.ai_forecast_operations.forecast_pm25_org1 manual__2025-04-22T22:29:36.102757+00:00 [queued]>
[2025-04-22T22:30:19.799+0000] {taskinstance.py:1361} INFO - Starting attempt 1 of 2
[2025-04-22T22:30:19.809+0000] {taskinstance.py:1382} INFO - Executing <Task(PythonOperator): ai_forecast_operations.forecast_pm25_org1> on 2025-04-22 22:29:36.102757+00:00
[2025-04-22T22:30:19.813+0000] {standard_task_runner.py:57} INFO - Started process 1516 to run task
[2025-04-22T22:30:19.815+0000] {standard_task_runner.py:84} INFO - Running: ['airflow', 'tasks', 'run', 'weather_data_pipeline', 'ai_forecast_operations.forecast_pm25_org1', 'manual__2025-04-22T22:29:36.102757+00:00', '--job-id', '28', '--raw', '--subdir', 'DAGS_FOLDER/data_pipeline.py', '--cfg-path', '/tmp/tmpr6737lie']
[2025-04-22T22:30:19.816+0000] {standard_task_runner.py:85} INFO - Job 28: Subtask ai_forecast_operations.forecast_pm25_org1
[2025-04-22T22:30:19.846+0000] {task_command.py:415} INFO - Running <TaskInstance: weather_data_pipeline.ai_forecast_operations.forecast_pm25_org1 manual__2025-04-22T22:29:36.102757+00:00 [running]> on host ba2ad926eb92
[2025-04-22T22:30:19.897+0000] {taskinstance.py:1660} INFO - Exporting env vars: AIRFLOW_CTX_DAG_OWNER='airflow' AIRFLOW_CTX_DAG_ID='weather_data_pipeline' AIRFLOW_CTX_TASK_ID='ai_forecast_operations.forecast_pm25_org1' AIRFLOW_CTX_EXECUTION_DATE='2025-04-22T22:29:36.102757+00:00' AIRFLOW_CTX_TRY_NUMBER='1' AIRFLOW_CTX_DAG_RUN_ID='manual__2025-04-22T22:29:36.102757+00:00'
[2025-04-22T22:30:19.906+0000] {taskinstance.py:1943} ERROR - Task failed with exception
Traceback (most recent call last):
  File "/home/airflow/.local/lib/python3.8/site-packages/airflow/operators/python.py", line 192, in execute
    return_value = self.execute_callable()
  File "/home/airflow/.local/lib/python3.8/site-packages/airflow/operators/python.py", line 209, in execute_callable
    return self.python_callable(*self.op_args, **self.op_kwargs)
  File "/opt/airflow/src/ai/forecast.py", line 51, in forecast_next_week_and_store
    df
  File "/home/airflow/.local/lib/python3.8/site-packages/pandas/core/frame.py", line 10994, in resample
    return super().resample(
  File "/home/airflow/.local/lib/python3.8/site-packages/pandas/core/generic.py", line 8888, in resample
    return get_resampler(
  File "/home/airflow/.local/lib/python3.8/site-packages/pandas/core/resample.py", line 1523, in get_resampler
    return tg._get_resampler(obj, kind=kind)
  File "/home/airflow/.local/lib/python3.8/site-packages/pandas/core/resample.py", line 1713, in _get_resampler
    raise TypeError(
TypeError: Only valid with DatetimeIndex, TimedeltaIndex or PeriodIndex, but got an instance of 'Index'
[2025-04-22T22:30:19.917+0000] {taskinstance.py:1400} INFO - Marking task as UP_FOR_RETRY. dag_id=weather_data_pipeline, task_id=ai_forecast_operations.forecast_pm25_org1, execution_date=20250422T222936, start_date=20250422T223019, end_date=20250422T223019
[2025-04-22T22:30:19.924+0000] {standard_task_runner.py:104} ERROR - Failed to execute job 28 for task ai_forecast_operations.forecast_pm25_org1 (Only valid with DatetimeIndex, TimedeltaIndex or PeriodIndex, but got an instance of 'Index'; 1516)
[2025-04-22T22:30:19.948+0000] {local_task_job_runner.py:228} INFO - Task exited with return code 1
[2025-04-22T22:30:19.963+0000] {taskinstance.py:2784} INFO - 0 downstream tasks scheduled from follow-on schedule check
