[2025-04-20T22:27:35.696+0000] {local_task_job_runner.py:123} INFO - ::group::Pre task execution logs
[2025-04-20T22:27:35.708+0000] {taskinstance.py:2614} INFO - Dependencies all met for dep_context=non-requeueable deps ti=<TaskInstance: weather_data_pipeline.db_view_operations.create_map_data_view manual__2025-04-20T22:20:54.044318+00:00 [queued]>
[2025-04-20T22:27:35.714+0000] {taskinstance.py:2614} INFO - Dependencies all met for dep_context=requeueable deps ti=<TaskInstance: weather_data_pipeline.db_view_operations.create_map_data_view manual__2025-04-20T22:20:54.044318+00:00 [queued]>
[2025-04-20T22:27:35.714+0000] {taskinstance.py:2867} INFO - Starting attempt 2 of 2
[2025-04-20T22:27:35.722+0000] {taskinstance.py:2890} INFO - Executing <Task(PythonOperator): db_view_operations.create_map_data_view> on 2025-04-20 22:20:54.044318+00:00
[2025-04-20T22:27:35.727+0000] {standard_task_runner.py:104} INFO - Running: ['airflow', 'tasks', 'run', 'weather_data_pipeline', 'db_view_operations.create_map_data_view', 'manual__2025-04-20T22:20:54.044318+00:00', '--job-id', '195', '--raw', '--subdir', 'DAGS_FOLDER/data_pipeline.py', '--cfg-path', '/tmp/tmp35n4irr3']
[2025-04-20T22:27:35.728+0000] {standard_task_runner.py:105} INFO - Job 195: Subtask db_view_operations.create_map_data_view
[2025-04-20T22:27:35.729+0000] {logging_mixin.py:190} WARNING - /home/airflow/.local/lib/python3.12/site-packages/airflow/task/task_runner/standard_task_runner.py:70 DeprecationWarning: This process (pid=1028) is multi-threaded, use of fork() may lead to deadlocks in the child.
[2025-04-20T22:27:35.730+0000] {standard_task_runner.py:72} INFO - Started process 1050 to run task
[2025-04-20T22:27:35.755+0000] {task_command.py:467} INFO - Running <TaskInstance: weather_data_pipeline.db_view_operations.create_map_data_view manual__2025-04-20T22:20:54.044318+00:00 [running]> on host 8e2c8626a9ef
[2025-04-20T22:27:35.799+0000] {taskinstance.py:3134} INFO - Exporting env vars: AIRFLOW_CTX_DAG_OWNER='airflow' AIRFLOW_CTX_DAG_ID='weather_data_pipeline' AIRFLOW_CTX_TASK_ID='db_view_operations.create_map_data_view' AIRFLOW_CTX_EXECUTION_DATE='2025-04-20T22:20:54.044318+00:00' AIRFLOW_CTX_TRY_NUMBER='2' AIRFLOW_CTX_DAG_RUN_ID='manual__2025-04-20T22:20:54.044318+00:00'
[2025-04-20T22:27:35.800+0000] {taskinstance.py:732} INFO - ::endgroup::
[2025-04-20T22:27:35.812+0000] {logging_mixin.py:190} INFO - Error executing SQL: column l.organization_id does not exist
LINE 7:         l.organization_id,  -- Include organization_id from ...
                ^
HINT:  Perhaps you meant to reference the column "m.organization_id".
[2025-04-20T22:27:35.813+0000] {taskinstance.py:3313} ERROR - Task failed with exception
Traceback (most recent call last):
  File "/home/airflow/.local/lib/python3.12/site-packages/airflow/models/taskinstance.py", line 768, in _execute_task
    result = _execute_callable(context=context, **execute_callable_kwargs)
             ^^^^^^^^^^^^^^^^^^^^^^^^^^^^^^^^^^^^^^^^^^^^^^^^^^^^^^^^^^^^^
  File "/home/airflow/.local/lib/python3.12/site-packages/airflow/models/taskinstance.py", line 734, in _execute_callable
    return ExecutionCallableRunner(
           ^^^^^^^^^^^^^^^^^^^^^^^^
  File "/home/airflow/.local/lib/python3.12/site-packages/airflow/utils/operator_helpers.py", line 252, in run
    return self.func(*args, **kwargs)
           ^^^^^^^^^^^^^^^^^^^^^^^^^^
  File "/home/airflow/.local/lib/python3.12/site-packages/airflow/models/baseoperator.py", line 424, in wrapper
    return func(self, *args, **kwargs)
           ^^^^^^^^^^^^^^^^^^^^^^^^^^^
  File "/home/airflow/.local/lib/python3.12/site-packages/airflow/operators/python.py", line 238, in execute
    return_value = self.execute_callable()
                   ^^^^^^^^^^^^^^^^^^^^^^^
  File "/home/airflow/.local/lib/python3.12/site-packages/airflow/operators/python.py", line 256, in execute_callable
    return runner.run(*self.op_args, **self.op_kwargs)
           ^^^^^^^^^^^^^^^^^^^^^^^^^^^^^^^^^^^^^^^^^^^
  File "/home/airflow/.local/lib/python3.12/site-packages/airflow/utils/operator_helpers.py", line 252, in run
    return self.func(*args, **kwargs)
           ^^^^^^^^^^^^^^^^^^^^^^^^^^
  File "/opt/airflow/dags/operators/db_operations.py", line 53, in create_map_data_view
    execute_sql_file(sql_file_path)
  File "/opt/airflow/dags/operators/db_operations.py", line 33, in execute_sql_file
    cursor.execute(sql)
psycopg2.errors.UndefinedColumn: column l.organization_id does not exist
LINE 7:         l.organization_id,  -- Include organization_id from ...
                ^
HINT:  Perhaps you meant to reference the column "m.organization_id".

[2025-04-20T22:27:35.820+0000] {taskinstance.py:1226} INFO - Marking task as FAILED. dag_id=weather_data_pipeline, task_id=db_view_operations.create_map_data_view, run_id=manual__2025-04-20T22:20:54.044318+00:00, execution_date=20250420T222054, start_date=20250420T222735, end_date=20250420T222735
[2025-04-20T22:27:35.835+0000] {taskinstance.py:341} INFO - ::group::Post task execution logs
[2025-04-20T22:27:35.836+0000] {standard_task_runner.py:124} ERROR - Failed to execute job 195 for task db_view_operations.create_map_data_view (column l.organization_id does not exist
LINE 7:         l.organization_id,  -- Include organization_id from ...
                ^
HINT:  Perhaps you meant to reference the column "m.organization_id".
; 1050)
Traceback (most recent call last):
  File "/home/airflow/.local/lib/python3.12/site-packages/airflow/task/task_runner/standard_task_runner.py", line 117, in _start_by_fork
    ret = args.func(args, dag=self.dag)
          ^^^^^^^^^^^^^^^^^^^^^^^^^^^^^
  File "/home/airflow/.local/lib/python3.12/site-packages/airflow/cli/cli_config.py", line 49, in command
    return func(*args, **kwargs)
           ^^^^^^^^^^^^^^^^^^^^^
  File "/home/airflow/.local/lib/python3.12/site-packages/airflow/utils/cli.py", line 116, in wrapper
    return f(*args, **kwargs)
           ^^^^^^^^^^^^^^^^^^
  File "/home/airflow/.local/lib/python3.12/site-packages/airflow/cli/commands/task_command.py", line 483, in task_run
    task_return_code = _run_task_by_selected_method(args, _dag, ti)
                       ^^^^^^^^^^^^^^^^^^^^^^^^^^^^^^^^^^^^^^^^^^^^
  File "/home/airflow/.local/lib/python3.12/site-packages/airflow/cli/commands/task_command.py", line 256, in _run_task_by_selected_method
    return _run_raw_task(args, ti)
           ^^^^^^^^^^^^^^^^^^^^^^^
  File "/home/airflow/.local/lib/python3.12/site-packages/airflow/cli/commands/task_command.py", line 341, in _run_raw_task
    return ti._run_raw_task(
           ^^^^^^^^^^^^^^^^^
  File "/home/airflow/.local/lib/python3.12/site-packages/airflow/utils/session.py", line 97, in wrapper
    return func(*args, session=session, **kwargs)
           ^^^^^^^^^^^^^^^^^^^^^^^^^^^^^^^^^^^^^^
  File "/home/airflow/.local/lib/python3.12/site-packages/airflow/models/taskinstance.py", line 3006, in _run_raw_task
    return _run_raw_task(
           ^^^^^^^^^^^^^^
  File "/home/airflow/.local/lib/python3.12/site-packages/airflow/models/taskinstance.py", line 274, in _run_raw_task
    TaskInstance._execute_task_with_callbacks(
  File "/home/airflow/.local/lib/python3.12/site-packages/airflow/models/taskinstance.py", line 3161, in _execute_task_with_callbacks
    result = self._execute_task(context, task_orig)
             ^^^^^^^^^^^^^^^^^^^^^^^^^^^^^^^^^^^^^^
  File "/home/airflow/.local/lib/python3.12/site-packages/airflow/models/taskinstance.py", line 3185, in _execute_task
    return _execute_task(self, context, task_orig)
           ^^^^^^^^^^^^^^^^^^^^^^^^^^^^^^^^^^^^^^^
  File "/home/airflow/.local/lib/python3.12/site-packages/airflow/models/taskinstance.py", line 768, in _execute_task
    result = _execute_callable(context=context, **execute_callable_kwargs)
             ^^^^^^^^^^^^^^^^^^^^^^^^^^^^^^^^^^^^^^^^^^^^^^^^^^^^^^^^^^^^^
  File "/home/airflow/.local/lib/python3.12/site-packages/airflow/models/taskinstance.py", line 734, in _execute_callable
    return ExecutionCallableRunner(
           ^^^^^^^^^^^^^^^^^^^^^^^^
  File "/home/airflow/.local/lib/python3.12/site-packages/airflow/utils/operator_helpers.py", line 252, in run
    return self.func(*args, **kwargs)
           ^^^^^^^^^^^^^^^^^^^^^^^^^^
  File "/home/airflow/.local/lib/python3.12/site-packages/airflow/models/baseoperator.py", line 424, in wrapper
    return func(self, *args, **kwargs)
           ^^^^^^^^^^^^^^^^^^^^^^^^^^^
  File "/home/airflow/.local/lib/python3.12/site-packages/airflow/operators/python.py", line 238, in execute
    return_value = self.execute_callable()
                   ^^^^^^^^^^^^^^^^^^^^^^^
  File "/home/airflow/.local/lib/python3.12/site-packages/airflow/operators/python.py", line 256, in execute_callable
    return runner.run(*self.op_args, **self.op_kwargs)
           ^^^^^^^^^^^^^^^^^^^^^^^^^^^^^^^^^^^^^^^^^^^
  File "/home/airflow/.local/lib/python3.12/site-packages/airflow/utils/operator_helpers.py", line 252, in run
    return self.func(*args, **kwargs)
           ^^^^^^^^^^^^^^^^^^^^^^^^^^
  File "/opt/airflow/dags/operators/db_operations.py", line 53, in create_map_data_view
    execute_sql_file(sql_file_path)
  File "/opt/airflow/dags/operators/db_operations.py", line 33, in execute_sql_file
    cursor.execute(sql)
psycopg2.errors.UndefinedColumn: column l.organization_id does not exist
LINE 7:         l.organization_id,  -- Include organization_id from ...
                ^
HINT:  Perhaps you meant to reference the column "m.organization_id".

[2025-04-20T22:27:35.863+0000] {local_task_job_runner.py:266} INFO - Task exited with return code 1
[2025-04-20T22:27:35.877+0000] {taskinstance.py:3901} INFO - 0 downstream tasks scheduled from follow-on schedule check
[2025-04-20T22:27:35.879+0000] {local_task_job_runner.py:245} INFO - ::endgroup::
